Workbook
Name AFA_Types: OFFSET(Lists!$H$6,0,0,MAX(1,COUNTA(Lists!$A$5:$A$34)),1)
Name AFA_Types_All: Lists!$H$6:$H$35
Name Schedule_List: OFFSET(Lists!$H$5,0,0,1+COUNTA(Lists!$A$5:$A$34),1)
Name Cyber_List: OFFSET(Lists!$D$5,0,0,MAX(1,COUNTA(Lists!$D$5:$D$19)),1)
Name Status_List: Lists!$F$5:$F$6
Name Role_List: Lists!$J$5:$J$12
Name State_Codes: Lists!$L$5:$L$55
Name Firm_List: OFFSET(Lists!$O$5,0,0,MAX(1,COUNTA(Firms!$A$5:$A$1004)),1)
Name Firms_AZ: Lists!$O$5:$O$1004
Name Review_Months: Lists!$R$5

Sheet Home
B2: Outside Counsel Rate & Panel Tracker
B3: The approved source for agreed firm rates — for approving rate submissions and for compliance review.
B5: TABS
B6: =HYPERLINK("#'Firm Search'!A1","Firm Search ›") | C6: Look up one firm: status, states, dates, cyber status, standard rates, every AFA and its rate history.
B7: =HYPERLINK("#'Rate Check'!A1","Rate Check ›") | C7: Approving a rate submission? Enter the lines — each is marked ✓ Approve / ✗ Exceeds against the rate in effect on the date of service.
B8: =HYPERLINK("#'State Search'!A1","State Search ›") | C8: Pick a state → every active firm approved there, with rates.
B9: =HYPERLINK("#'Firms'!A1","Firms ›") | C9: Master list: Status, Approved States, Approved Since, Rates Effective, 8 standard rates, Cyber Status, pause info, Notes.
B10: =HYPERLINK("#'AFA Rates'!A1","AFA Rates ›") | C10: One row per firm per AFA type: Effective / End dates and the AFA rate for every role.
B11: =HYPERLINK("#'Rate History'!A1","Rate History ›") | C11: Superseded rates with From / To dates. Log old rates here before changing them.
B12: =HYPERLINK("#'All Current Rates'!A1","All Current Rates ›") | C12: Compliance view: every agreed rate (standard + AFA) in one filterable table. Automatic.
B13: =HYPERLINK("#'Do Not Use'!A1","Do Not Use ›") | C13: Automatic list of every firm whose Status is “Paused”.
B14: =HYPERLINK("#'Summary'!A1","Summary ›") | C14: Reporting counts: firms, AFAs, rate reviews due, cyber status, coverage by state.
B15: =HYPERLINK("#'Lists'!A1","Lists ›") | C15: Dropdown options (AFA types, cyber statuses) and the rate-review period (default 12 months).
B17: HOW TO…
B18: Add a firm | C18: Firms → next empty row. Fill Status, Approved States, Approved Since, Rates Effective, the 8 rates, Cyber Status, Notes.
B19: Add an AFA | C19: AFA Rates → next empty row → pick Firm and AFA Type → Effective Date (End Date optional) → the AFA rates.
B20: Change agreed rates | C20: 1) Rate History → new row: Firm, Schedule (Standard or AFA type), the OLD rates, From = old effective date, To = day before the new rates start. 2) Then overwrite the rates and effective date on Firms (or AFA Rates).
B21: Approve a submission | C21: Rate Check → pick the firm → one line per timekeeper (schedule, role, date of service, submitted rate). Clear the white cells when done.
B22: Add a new AFA type | C22: Lists → type it in the next empty yellow cell. It appears in every dropdown, search and summary.
B23: Pause / reinstate | C23: Firms → Status “Paused” (+ Date Paused, Pause Reason). Back to “Active” to reinstate.
B24: Locked cells | C24: Gray / automatic cells are locked so formulas can't be overwritten. To change the structure: Review → Unprotect Sheet (no password). Re-protect afterwards. Filters work while protected; sorting needs the sheet unprotected.
B25: Remove sample data | C25: Firms starting “Sample:” are examples. Clear their cells on Firms, AFA Rates, Rate History and Rate Check before going live.
B27: LEGEND
B28: White cell | C28: You type here.
B29: Gray cell / slate header | C29: Automatic — locked.
B30: Yellow cell | C30: Editable options / settings (Lists tab).
B31: Review Due | C31: Rates older than the review period (Lists tab).
B32: Red | C32: Duplicate entry, expired AFA, paused firm, or a Rate History problem.
B34: Capacity: 1,000 firms · 1,000 AFA rows · 2,000 Rate History rows · 30 AFA types. Rates are hourly, USD.

Sheet Firm Search
B2: 🔎 Firm Search
B3: Type a firm name (or part of one) in the box below, or click the box and use the ▼ dropdown.
B5: Search for a firm: | C5: Brookstone | H5: ◄ type here
B7: Showing results for: | C7: =IF($C$5="","",IFERROR(INDEX(Firms!$A$5:$A$1004,MATCH($C$5,Firms!$A$5:$A$1004,0)),IFERROR(INDEX(Firms_AZ,MATCH("*"&$C$5&"*",Firms_AZ,0)),"No matching firm found"))) | G7: =IF(OR($C$5="",ISNUMBER(MATCH($C$5,Firms!$A$5:$A$1004,0))),"",IF(COUNTIF(Firms!$A$5:$A$1004,"*"&$C$5&"*")>1,COUNTIF(Firms!$A$5:$A$1004,"*"&$C$5&"*")&" firms match — showing the first A–Z. Be more specific or use ▼.","")) | O7: =IFERROR(MATCH($C$7,Firms!$A$5:$A$1004,0),"")
B9: =IF($O$7="",IF($C$5="","Enter a firm name above to see its details.","No firm matches that search — check spelling."),IF(INDEX(Firms!$B$5:$B$1004,$O$7)="Paused","⛔ DO NOT USE — this firm is PAUSED"&IF(INDEX(Firms!$S$5:$S$1004,$O$7)<>"",": "&INDEX(Firms!$S$5:$S$1004,$O$7),""),"✓ ACTIVE — approved for use"))
B11: FIRM PROFILE
B12: Status | C12: =IF($O$7="","",INDEX(Firms!$B$5:$B$1004,$O$7)&"")
B13: Approved States | C13: =IF($O$7="","",IF(INDEX(Firms!$C$5:$C$1004,$O$7)="","—",INDEX(Firms!$C$5:$C$1004,$O$7)))
B14: Approved Since | C14: =IF($O$7="","",IF(INDEX(Firms!$D$5:$D$1004,$O$7)="","—",TEXT(INDEX(Firms!$D$5:$D$1004,$O$7),"mm/dd/yyyy")))
B15: Standard Rates Effective | C15: =IF($O$7="","",IF(INDEX(Firms!$E$5:$E$1004,$O$7)="","—",TEXT(INDEX(Firms!$E$5:$E$1004,$O$7),"mm/dd/yyyy"))&" · "&INDEX(Firms!$O$5:$O$1004,$O$7))
B16: Cyber Status | C16: =IF($O$7="","",IF(INDEX(Firms!$N$5:$N$1004,$O$7)="","—",INDEX(Firms!$N$5:$N$1004,$O$7)))
B17: AFA on File? | C17: =IF($O$7="","",INDEX(Firms!$P$5:$P$1004,$O$7)&IF(INDEX(Firms!$Q$5:$Q$1004,$O$7)>0," — "&INDEX(Firms!$Q$5:$Q$1004,$O$7)&" active AFA(s)",""))
B18: Paused | C18: =IF($O$7="","",IF(INDEX(Firms!$B$5:$B$1004,$O$7)<>"Paused","—",IF(INDEX(Firms!$R$5:$R$1004,$O$7)="","—",TEXT(INDEX(Firms!$R$5:$R$1004,$O$7),"mm/dd/yyyy"))&IF(INDEX(Firms!$S$5:$S$1004,$O$7)<>""," · "&INDEX(Firms!$S$5:$S$1004,$O$7),"")))
B19: Rate History | C19: =IF($O$7="","",COUNTIF('Rate History'!$A$5:$A$2004,$C$7)&" prior rate row(s) on file — shown below")
B20: Notes | C20: =IF($O$7="","",IF(INDEX(Firms!$T$5:$T$1004,$O$7)="","—",INDEX(Firms!$T$5:$T$1004,$O$7)))
B22: STANDARD HOURLY RATES
B23: Schedule | C23: Counsel | D23: Senior Partner | E23: Junior Partner | F23: Partner | G23: Senior Associate | H23: Junior Associate | I23: Associate | J23: Paralegal | K23: Effective | L23: Ends | M23: Status
B24: =IF($O$7="","","Standard") | C24: =IF($O$7="","",IF(INDEX(Firms!$F$5:$F$1004,$O$7)="","—",INDEX(Firms!$F$5:$F$1004,$O$7))) | D24: =IF($O$7="","",IF(INDEX(Firms!$G$5:$G$1004,$O$7)="","—",INDEX(Firms!$G$5:$G$1004,$O$7))) | E24: =IF($O$7="","",IF(INDEX(Firms!$H$5:$H$1004,$O$7)="","—",INDEX(Firms!$H$5:$H$1004,$O$7))) | F24: =IF($O$7="","",IF(INDEX(Firms!$I$5:$I$1004,$O$7)="","—",INDEX(Firms!$I$5:$I$1004,$O$7))) | G24: =IF($O$7="","",IF(INDEX(Firms!$J$5:$J$1004,$O$7)="","—",INDEX(Firms!$J$5:$J$1004,$O$7))) | H24: =IF($O$7="","",IF(INDEX(Firms!$K$5:$K$1004,$O$7)="","—",INDEX(Firms!$K$5:$K$1004,$O$7))) | I24: =IF($O$7="","",IF(INDEX(Firms!$L$5:$L$1004,$O$7)="","—",INDEX(Firms!$L$5:$L$1004,$O$7))) | J24: =IF($O$7="","",IF(INDEX(Firms!$M$5:$M$1004,$O$7)="","—",INDEX(Firms!$M$5:$M$1004,$O$7))) | K24: =IF($O$7="","",IF(INDEX(Firms!$E$5:$E$1004,$O$7)="","—",TEXT(INDEX(Firms!$E$5:$E$1004,$O$7),"mm/dd/yyyy"))) | L24: =IF($O$7="","","—") | M24: =IF($O$7="","",INDEX(Firms!$O$5:$O$1004,$O$7))
B26: AFA RATES (Alternative Fee Arrangements)
B27: AFA Type | C27: Counsel | D27: Senior Partner | E27: Junior Partner | F27: Partner | G27: Senior Associate | H27: Junior Associate | I27: Associate | J27: Paralegal | K27: Effective | L27: Ends | M27: Status
B28: =IF($P28="","",INDEX('AFA Rates'!$B$5:$B$1004,$P28)&"") | C28: =IF($P28="","",IF(INDEX('AFA Rates'!$E$5:$E$1004,$P28)="","—",INDEX('AFA Rates'!$E$5:$E$1004,$P28))) | D28: =IF($P28="","",IF(INDEX('AFA Rates'!$F$5:$F$1004,$P28)="","—",INDEX('AFA Rates'!$F$5:$F$1004,$P28))) | E28: =IF($P28="","",IF(INDEX('AFA Rates'!$G$5:$G$1004,$P28)="","—",INDEX('AFA Rates'!$G$5:$G$1004,$P28))) | F28: =IF($P28="","",IF(INDEX('AFA Rates'!$H$5:$H$1004,$P28)="","—",INDEX('AFA Rates'!$H$5:$H$1004,$P28))) | G28: =IF($P28="","",IF(INDEX('AFA Rates'!$I$5:$I$1004,$P28)="","—",INDEX('AFA Rates'!$I$5:$I$1004,$P28))) | H28: =IF($P28="","",IF(INDEX('AFA Rates'!$J$5:$J$1004,$P28)="","—",INDEX('AFA Rates'!$J$5:$J$1004,$P28))) | I28: =IF($P28="","",IF(INDEX('AFA Rates'!$K$5:$K$1004,$P28)="","—",INDEX('AFA Rates'!$K$5:$K$1004,$P28))) | J28: =IF($P28="","",IF(INDEX('AFA Rates'!$L$5:$L$1004,$P28)="","—",INDEX('AFA Rates'!$L$5:$L$1004,$P28))) | K28: =IF($P28="","",IF(INDEX('AFA Rates'!$C$5:$C$1004,$P28)="","—",TEXT(INDEX('AFA Rates'!$C$5:$C$1004,$P28),"mm/dd/yyyy"))) | L28: =IF($P28="","",IF(INDEX('AFA Rates'!$D$5:$D$1004,$P28)="","—",TEXT(INDEX('AFA Rates'!$D$5:$D$1004,$P28),"mm/dd/yyyy"))) | M28: =IF($P28="","",INDEX('AFA Rates'!$O$5:$O$1004,$P28)) | P28: =IFERROR(MATCH(1,'AFA Rates'!$Q$5:$Q$1004,0),"")
B29: =IF($P29="","",INDEX('AFA Rates'!$B$5:$B$1004,$P29)&"") | C29: =IF($P29="","",IF(INDEX('AFA Rates'!$E$5:$E$1004,$P29)="","—",INDEX('AFA Rates'!$E$5:$E$1004,$P29))) | D29: =IF($P29="","",IF(INDEX('AFA Rates'!$F$5:$F$1004,$P29)="","—",INDEX('AFA Rates'!$F$5:$F$1004,$P29))) | E29: =IF($P29="","",IF(INDEX('AFA Rates'!$G$5:$G$1004,$P29)="","—",INDEX('AFA Rates'!$G$5:$G$1004,$P29))) | F29: =IF($P29="","",IF(INDEX('AFA Rates'!$H$5:$H$1004,$P29)="","—",INDEX('AFA Rates'!$H$5:$H$1004,$P29))) | G29: =IF($P29="","",IF(INDEX('AFA Rates'!$I$5:$I$1004,$P29)="","—",INDEX('AFA Rates'!$I$5:$I$1004,$P29))) | H29: =IF($P29="","",IF(INDEX('AFA Rates'!$J$5:$J$1004,$P29)="","—",INDEX('AFA Rates'!$J$5:$J$1004,$P29))) | I29: =IF($P29="","",IF(INDEX('AFA Rates'!$K$5:$K$1004,$P29)="","—",INDEX('AFA Rates'!$K$5:$K$1004,$P29))) | J29: =IF($P29="","",IF(INDEX('AFA Rates'!$L$5:$L$1004,$P29)="","—",INDEX('AFA Rates'!$L$5:$L$1004,$P29))) | K29: =IF($P29="","",IF(INDEX('AFA Rates'!$C$5:$C$1004,$P29)="","—",TEXT(INDEX('AFA Rates'!$C$5:$C$1004,$P29),"mm/dd/yyyy"))) | L29: =IF($P29="","",IF(INDEX('AFA Rates'!$D$5:$D$1004,$P29)="","—",TEXT(INDEX('AFA Rates'!$D$5:$D$1004,$P29),"mm/dd/yyyy"))) | M29: =IF($P29="","",INDEX('AFA Rates'!$O$5:$O$1004,$P29)) | P29: =IFERROR(MATCH(2,'AFA Rates'!$Q$5:$Q$1004,0),"")
B30: =IF($P30="","",INDEX('AFA Rates'!$B$5:$B$1004,$P30)&"") | C30: =IF($P30="","",IF(INDEX('AFA Rates'!$E$5:$E$1004,$P30)="","—",INDEX('AFA Rates'!$E$5:$E$1004,$P30))) | D30: =IF($P30="","",IF(INDEX('AFA Rates'!$F$5:$F$1004,$P30)="","—",INDEX('AFA Rates'!$F$5:$F$1004,$P30))) | E30: =IF($P30="","",IF(INDEX('AFA Rates'!$G$5:$G$1004,$P30)="","—",INDEX('AFA Rates'!$G$5:$G$1004,$P30))) | F30: =IF($P30="","",IF(INDEX('AFA Rates'!$H$5:$H$1004,$P30)="","—",INDEX('AFA Rates'!$H$5:$H$1004,$P30))) | G30: =IF($P30="","",IF(INDEX('AFA Rates'!$I$5:$I$1004,$P30)="","—",INDEX('AFA Rates'!$I$5:$I$1004,$P30))) | H30: =IF($P30="","",IF(INDEX('AFA Rates'!$J$5:$J$1004,$P30)="","—",INDEX('AFA Rates'!$J$5:$J$1004,$P30))) | I30: =IF($P30="","",IF(INDEX('AFA Rates'!$K$5:$K$1004,$P30)="","—",INDEX('AFA Rates'!$K$5:$K$1004,$P30))) | J30: =IF($P30="","",IF(INDEX('AFA Rates'!$L$5:$L$1004,$P30)="","—",INDEX('AFA Rates'!$L$5:$L$1004,$P30))) | K30: =IF($P30="","",IF(INDEX('AFA Rates'!$C$5:$C$1004,$P30)="","—",TEXT(INDEX('AFA Rates'!$C$5:$C$1004,$P30),"mm/dd/yyyy"))) | L30: =IF($P30="","",IF(INDEX('AFA Rates'!$D$5:$D$1004,$P30)="","—",TEXT(INDEX('AFA Rates'!$D$5:$D$1004,$P30),"mm/dd/yyyy"))) | M30: =IF($P30="","",INDEX('AFA Rates'!$O$5:$O$1004,$P30)) | P30: =IFERROR(MATCH(3,'AFA Rates'!$Q$5:$Q$1004,0),"")
B31: =IF($P31="","",INDEX('AFA Rates'!$B$5:$B$1004,$P31)&"") | C31: =IF($P31="","",IF(INDEX('AFA Rates'!$E$5:$E$1004,$P31)="","—",INDEX('AFA Rates'!$E$5:$E$1004,$P31))) | D31: =IF($P31="","",IF(INDEX('AFA Rates'!$F$5:$F$1004,$P31)="","—",INDEX('AFA Rates'!$F$5:$F$1004,$P31))) | E31: =IF($P31="","",IF(INDEX('AFA Rates'!$G$5:$G$1004,$P31)="","—",INDEX('AFA Rates'!$G$5:$G$1004,$P31))) | F31: =IF($P31="","",IF(INDEX('AFA Rates'!$H$5:$H$1004,$P31)="","—",INDEX('AFA Rates'!$H$5:$H$1004,$P31))) | G31: =IF($P31="","",IF(INDEX('AFA Rates'!$I$5:$I$1004,$P31)="","—",INDEX('AFA Rates'!$I$5:$I$1004,$P31))) | H31: =IF($P31="","",IF(INDEX('AFA Rates'!$J$5:$J$1004,$P31)="","—",INDEX('AFA Rates'!$J$5:$J$1004,$P31))) | I31: =IF($P31="","",IF(INDEX('AFA Rates'!$K$5:$K$1004,$P31)="","—",INDEX('AFA Rates'!$K$5:$K$1004,$P31))) | J31: =IF($P31="","",IF(INDEX('AFA Rates'!$L$5:$L$1004,$P31)="","—",INDEX('AFA Rates'!$L$5:$L$1004,$P31))) | K31: =IF($P31="","",IF(INDEX('AFA Rates'!$C$5:$C$1004,$P31)="","—",TEXT(INDEX('AFA Rates'!$C$5:$C$1004,$P31),"mm/dd/yyyy"))) | L31: =IF($P31="","",IF(INDEX('AFA Rates'!$D$5:$D$1004,$P31)="","—",TEXT(INDEX('AFA Rates'!$D$5:$D$1004,$P31),"mm/dd/yyyy"))) | M31: =IF($P31="","",INDEX('AFA Rates'!$O$5:$O$1004,$P31)) | P31: =IFERROR(MATCH(4,'AFA Rates'!$Q$5:$Q$1004,0),"")
B32: =IF($P32="","",INDEX('AFA Rates'!$B$5:$B$1004,$P32)&"") | C32: =IF($P32="","",IF(INDEX('AFA Rates'!$E$5:$E$1004,$P32)="","—",INDEX('AFA Rates'!$E$5:$E$1004,$P32))) | D32: =IF($P32="","",IF(INDEX('AFA Rates'!$F$5:$F$1004,$P32)="","—",INDEX('AFA Rates'!$F$5:$F$1004,$P32))) | E32: =IF($P32="","",IF(INDEX('AFA Rates'!$G$5:$G$1004,$P32)="","—",INDEX('AFA Rates'!$G$5:$G$1004,$P32))) | F32: =IF($P32="","",IF(INDEX('AFA Rates'!$H$5:$H$1004,$P32)="","—",INDEX('AFA Rates'!$H$5:$H$1004,$P32))) | G32: =IF($P32="","",IF(INDEX('AFA Rates'!$I$5:$I$1004,$P32)="","—",INDEX('AFA Rates'!$I$5:$I$1004,$P32))) | H32: =IF($P32="","",IF(INDEX('AFA Rates'!$J$5:$J$1004,$P32)="","—",INDEX('AFA Rates'!$J$5:$J$1004,$P32))) | I32: =IF($P32="","",IF(INDEX('AFA Rates'!$K$5:$K$1004,$P32)="","—",INDEX('AFA Rates'!$K$5:$K$1004,$P32))) | J32: =IF($P32="","",IF(INDEX('AFA Rates'!$L$5:$L$1004,$P32)="","—",INDEX('AFA Rates'!$L$5:$L$1004,$P32))) | K32: =IF($P32="","",IF(INDEX('AFA Rates'!$C$5:$C$1004,$P32)="","—",TEXT(INDEX('AFA Rates'!$C$5:$C$1004,$P32),"mm/dd/yyyy"))) | L32: =IF($P32="","",IF(INDEX('AFA Rates'!$D$5:$D$1004,$P32)="","—",TEXT(INDEX('AFA Rates'!$D$5:$D$1004,$P32),"mm/dd/yyyy"))) | M32: =IF($P32="","",INDEX('AFA Rates'!$O$5:$O$1004,$P32)) | P32: =IFERROR(MATCH(5,'AFA Rates'!$Q$5:$Q$1004,0),"")
B33: =IF($P33="","",INDEX('AFA Rates'!$B$5:$B$1004,$P33)&"") | C33: =IF($P33="","",IF(INDEX('AFA Rates'!$E$5:$E$1004,$P33)="","—",INDEX('AFA Rates'!$E$5:$E$1004,$P33))) | D33: =IF($P33="","",IF(INDEX('AFA Rates'!$F$5:$F$1004,$P33)="","—",INDEX('AFA Rates'!$F$5:$F$1004,$P33))) | E33: =IF($P33="","",IF(INDEX('AFA Rates'!$G$5:$G$1004,$P33)="","—",INDEX('AFA Rates'!$G$5:$G$1004,$P33))) | F33: =IF($P33="","",IF(INDEX('AFA Rates'!$H$5:$H$1004,$P33)="","—",INDEX('AFA Rates'!$H$5:$H$1004,$P33))) | G33: =IF($P33="","",IF(INDEX('AFA Rates'!$I$5:$I$1004,$P33)="","—",INDEX('AFA Rates'!$I$5:$I$1004,$P33))) | H33: =IF($P33="","",IF(INDEX('AFA Rates'!$J$5:$J$1004,$P33)="","—",INDEX('AFA Rates'!$J$5:$J$1004,$P33))) | I33: =IF($P33="","",IF(INDEX('AFA Rates'!$K$5:$K$1004,$P33)="","—",INDEX('AFA Rates'!$K$5:$K$1004,$P33))) | J33: =IF($P33="","",IF(INDEX('AFA Rates'!$L$5:$L$1004,$P33)="","—",INDEX('AFA Rates'!$L$5:$L$1004,$P33))) | K33: =IF($P33="","",IF(INDEX('AFA Rates'!$C$5:$C$1004,$P33)="","—",TEXT(INDEX('AFA Rates'!$C$5:$C$1004,$P33),"mm/dd/yyyy"))) | L33: =IF($P33="","",IF(INDEX('AFA Rates'!$D$5:$D$1004,$P33)="","—",TEXT(INDEX('AFA Rates'!$D$5:$D$1004,$P33),"mm/dd/yyyy"))) | M33: =IF($P33="","",INDEX('AFA Rates'!$O$5:$O$1004,$P33)) | P33: =IFERROR(MATCH(6,'AFA Rates'!$Q$5:$Q$1004,0),"")
B34: =IF($P34="","",INDEX('AFA Rates'!$B$5:$B$1004,$P34)&"") | C34: =IF($P34="","",IF(INDEX('AFA Rates'!$E$5:$E$1004,$P34)="","—",INDEX('AFA Rates'!$E$5:$E$1004,$P34))) | D34: =IF($P34="","",IF(INDEX('AFA Rates'!$F$5:$F$1004,$P34)="","—",INDEX('AFA Rates'!$F$5:$F$1004,$P34))) | E34: =IF($P34="","",IF(INDEX('AFA Rates'!$G$5:$G$1004,$P34)="","—",INDEX('AFA Rates'!$G$5:$G$1004,$P34))) | F34: =IF($P34="","",IF(INDEX('AFA Rates'!$H$5:$H$1004,$P34)="","—",INDEX('AFA Rates'!$H$5:$H$1004,$P34))) | G34: =IF($P34="","",IF(INDEX('AFA Rates'!$I$5:$I$1004,$P34)="","—",INDEX('AFA Rates'!$I$5:$I$1004,$P34))) | H34: =IF($P34="","",IF(INDEX('AFA Rates'!$J$5:$J$1004,$P34)="","—",INDEX('AFA Rates'!$J$5:$J$1004,$P34))) | I34: =IF($P34="","",IF(INDEX('AFA Rates'!$K$5:$K$1004,$P34)="","—",INDEX('AFA Rates'!$K$5:$K$1004,$P34))) | J34: =IF($P34="","",IF(INDEX('AFA Rates'!$L$5:$L$1004,$P34)="","—",INDEX('AFA Rates'!$L$5:$L$1004,$P34))) | K34: =IF($P34="","",IF(INDEX('AFA Rates'!$C$5:$C$1004,$P34)="","—",TEXT(INDEX('AFA Rates'!$C$5:$C$1004,$P34),"mm/dd/yyyy"))) | L34: =IF($P34="","",IF(INDEX('AFA Rates'!$D$5:$D$1004,$P34)="","—",TEXT(INDEX('AFA Rates'!$D$5:$D$1004,$P34),"mm/dd/yyyy"))) | M34: =IF($P34="","",INDEX('AFA Rates'!$O$5:$O$1004,$P34)) | P34: =IFERROR(MATCH(7,'AFA Rates'!$Q$5:$Q$1004,0),"")
B35: =IF($P35="","",INDEX('AFA Rates'!$B$5:$B$1004,$P35)&"") | C35: =IF($P35="","",IF(INDEX('AFA Rates'!$E$5:$E$1004,$P35)="","—",INDEX('AFA Rates'!$E$5:$E$1004,$P35))) | D35: =IF($P35="","",IF(INDEX('AFA Rates'!$F$5:$F$1004,$P35)="","—",INDEX('AFA Rates'!$F$5:$F$1004,$P35))) | E35: =IF($P35="","",IF(INDEX('AFA Rates'!$G$5:$G$1004,$P35)="","—",INDEX('AFA Rates'!$G$5:$G$1004,$P35))) | F35: =IF($P35="","",IF(INDEX('AFA Rates'!$H$5:$H$1004,$P35)="","—",INDEX('AFA Rates'!$H$5:$H$1004,$P35))) | G35: =IF($P35="","",IF(INDEX('AFA Rates'!$I$5:$I$1004,$P35)="","—",INDEX('AFA Rates'!$I$5:$I$1004,$P35))) | H35: =IF($P35="","",IF(INDEX('AFA Rates'!$J$5:$J$1004,$P35)="","—",INDEX('AFA Rates'!$J$5:$J$1004,$P35))) | I35: =IF($P35="","",IF(INDEX('AFA Rates'!$K$5:$K$1004,$P35)="","—",INDEX('AFA Rates'!$K$5:$K$1004,$P35))) | J35: =IF($P35="","",IF(INDEX('AFA Rates'!$L$5:$L$1004,$P35)="","—",INDEX('AFA Rates'!$L$5:$L$1004,$P35))) | K35: =IF($P35="","",IF(INDEX('AFA Rates'!$C$5:$C$1004,$P35)="","—",TEXT(INDEX('AFA Rates'!$C$5:$C$1004,$P35),"mm/dd/yyyy"))) | L35: =IF($P35="","",IF(INDEX('AFA Rates'!$D$5:$D$1004,$P35)="","—",TEXT(INDEX('AFA Rates'!$D$5:$D$1004,$P35),"mm/dd/yyyy"))) | M35: =IF($P35="","",INDEX('AFA Rates'!$O$5:$O$1004,$P35)) | P35: =IFERROR(MATCH(8,'AFA Rates'!$Q$5:$Q$1004,0),"")
B36: =IF($P36="","",INDEX('AFA Rates'!$B$5:$B$1004,$P36)&"") | C36: =IF($P36="","",IF(INDEX('AFA Rates'!$E$5:$E$1004,$P36)="","—",INDEX('AFA Rates'!$E$5:$E$1004,$P36))) | D36: =IF($P36="","",IF(INDEX('AFA Rates'!$F$5:$F$1004,$P36)="","—",INDEX('AFA Rates'!$F$5:$F$1004,$P36))) | E36: =IF($P36="","",IF(INDEX('AFA Rates'!$G$5:$G$1004,$P36)="","—",INDEX('AFA Rates'!$G$5:$G$1004,$P36))) | F36: =IF($P36="","",IF(INDEX('AFA Rates'!$H$5:$H$1004,$P36)="","—",INDEX('AFA Rates'!$H$5:$H$1004,$P36))) | G36: =IF($P36="","",IF(INDEX('AFA Rates'!$I$5:$I$1004,$P36)="","—",INDEX('AFA Rates'!$I$5:$I$1004,$P36))) | H36: =IF($P36="","",IF(INDEX('AFA Rates'!$J$5:$J$1004,$P36)="","—",INDEX('AFA Rates'!$J$5:$J$1004,$P36))) | I36: =IF($P36="","",IF(INDEX('AFA Rates'!$K$5:$K$1004,$P36)="","—",INDEX('AFA Rates'!$K$5:$K$1004,$P36))) | J36: =IF($P36="","",IF(INDEX('AFA Rates'!$L$5:$L$1004,$P36)="","—",INDEX('AFA Rates'!$L$5:$L$1004,$P36))) | K36: =IF($P36="","",IF(INDEX('AFA Rates'!$C$5:$C$1004,$P36)="","—",TEXT(INDEX('AFA Rates'!$C$5:$C$1004,$P36),"mm/dd/yyyy"))) | L36: =IF($P36="","",IF(INDEX('AFA Rates'!$D$5:$D$1004,$P36)="","—",TEXT(INDEX('AFA Rates'!$D$5:$D$1004,$P36),"mm/dd/yyyy"))) | M36: =IF($P36="","",INDEX('AFA Rates'!$O$5:$O$1004,$P36)) | P36: =IFERROR(MATCH(9,'AFA Rates'!$Q$5:$Q$1004,0),"")
B37: =IF($P37="","",INDEX('AFA Rates'!$B$5:$B$1004,$P37)&"") | C37: =IF($P37="","",IF(INDEX('AFA Rates'!$E$5:$E$1004,$P37)="","—",INDEX('AFA Rates'!$E$5:$E$1004,$P37))) | D37: =IF($P37="","",IF(INDEX('AFA Rates'!$F$5:$F$1004,$P37)="","—",INDEX('AFA Rates'!$F$5:$F$1004,$P37))) | E37: =IF($P37="","",IF(INDEX('AFA Rates'!$G$5:$G$1004,$P37)="","—",INDEX('AFA Rates'!$G$5:$G$1004,$P37))) | F37: =IF($P37="","",IF(INDEX('AFA Rates'!$H$5:$H$1004,$P37)="","—",INDEX('AFA Rates'!$H$5:$H$1004,$P37))) | G37: =IF($P37="","",IF(INDEX('AFA Rates'!$I$5:$I$1004,$P37)="","—",INDEX('AFA Rates'!$I$5:$I$1004,$P37))) | H37: =IF($P37="","",IF(INDEX('AFA Rates'!$J$5:$J$1004,$P37)="","—",INDEX('AFA Rates'!$J$5:$J$1004,$P37))) | I37: =IF($P37="","",IF(INDEX('AFA Rates'!$K$5:$K$1004,$P37)="","—",INDEX('AFA Rates'!$K$5:$K$1004,$P37))) | J37: =IF($P37="","",IF(INDEX('AFA Rates'!$L$5:$L$1004,$P37)="","—",INDEX('AFA Rates'!$L$5:$L$1004,$P37))) | K37: =IF($P37="","",IF(INDEX('AFA Rates'!$C$5:$C$1004,$P37)="","—",TEXT(INDEX('AFA Rates'!$C$5:$C$1004,$P37),"mm/dd/yyyy"))) | L37: =IF($P37="","",IF(INDEX('AFA Rates'!$D$5:$D$1004,$P37)="","—",TEXT(INDEX('AFA Rates'!$D$5:$D$1004,$P37),"mm/dd/yyyy"))) | M37: =IF($P37="","",INDEX('AFA Rates'!$O$5:$O$1004,$P37)) | P37: =IFERROR(MATCH(10,'AFA Rates'!$Q$5:$Q$1004,0),"")
B38: =IF($P38="","",INDEX('AFA Rates'!$B$5:$B$1004,$P38)&"") | C38: =IF($P38="","",IF(INDEX('AFA Rates'!$E$5:$E$1004,$P38)="","—",INDEX('AFA Rates'!$E$5:$E$1004,$P38))) | D38: =IF($P38="","",IF(INDEX('AFA Rates'!$F$5:$F$1004,$P38)="","—",INDEX('AFA Rates'!$F$5:$F$1004,$P38))) | E38: =IF($P38="","",IF(INDEX('AFA Rates'!$G$5:$G$1004,$P38)="","—",INDEX('AFA Rates'!$G$5:$G$1004,$P38))) | F38: =IF($P38="","",IF(INDEX('AFA Rates'!$H$5:$H$1004,$P38)="","—",INDEX('AFA Rates'!$H$5:$H$1004,$P38))) | G38: =IF($P38="","",IF(INDEX('AFA Rates'!$I$5:$I$1004,$P38)="","—",INDEX('AFA Rates'!$I$5:$I$1004,$P38))) | H38: =IF($P38="","",IF(INDEX('AFA Rates'!$J$5:$J$1004,$P38)="","—",INDEX('AFA Rates'!$J$5:$J$1004,$P38))) | I38: =IF($P38="","",IF(INDEX('AFA Rates'!$K$5:$K$1004,$P38)="","—",INDEX('AFA Rates'!$K$5:$K$1004,$P38))) | J38: =IF($P38="","",IF(INDEX('AFA Rates'!$L$5:$L$1004,$P38)="","—",INDEX('AFA Rates'!$L$5:$L$1004,$P38))) | K38: =IF($P38="","",IF(INDEX('AFA Rates'!$C$5:$C$1004,$P38)="","—",TEXT(INDEX('AFA Rates'!$C$5:$C$1004,$P38),"mm/dd/yyyy"))) | L38: =IF($P38="","",IF(INDEX('AFA Rates'!$D$5:$D$1004,$P38)="","—",TEXT(INDEX('AFA Rates'!$D$5:$D$1004,$P38),"mm/dd/yyyy"))) | M38: =IF($P38="","",INDEX('AFA Rates'!$O$5:$O$1004,$P38)) | P38: =IFERROR(MATCH(11,'AFA Rates'!$Q$5:$Q$1004,0),"")
B39: =IF($P39="","",INDEX('AFA Rates'!$B$5:$B$1004,$P39)&"") | C39: =IF($P39="","",IF(INDEX('AFA Rates'!$E$5:$E$1004,$P39)="","—",INDEX('AFA Rates'!$E$5:$E$1004,$P39))) | D39: =IF($P39="","",IF(INDEX('AFA Rates'!$F$5:$F$1004,$P39)="","—",INDEX('AFA Rates'!$F$5:$F$1004,$P39))) | E39: =IF($P39="","",IF(INDEX('AFA Rates'!$G$5:$G$1004,$P39)="","—",INDEX('AFA Rates'!$G$5:$G$1004,$P39))) | F39: =IF($P39="","",IF(INDEX('AFA Rates'!$H$5:$H$1004,$P39)="","—",INDEX('AFA Rates'!$H$5:$H$1004,$P39))) | G39: =IF($P39="","",IF(INDEX('AFA Rates'!$I$5:$I$1004,$P39)="","—",INDEX('AFA Rates'!$I$5:$I$1004,$P39))) | H39: =IF($P39="","",IF(INDEX('AFA Rates'!$J$5:$J$1004,$P39)="","—",INDEX('AFA Rates'!$J$5:$J$1004,$P39))) | I39: =IF($P39="","",IF(INDEX('AFA Rates'!$K$5:$K$1004,$P39)="","—",INDEX('AFA Rates'!$K$5:$K$1004,$P39))) | J39: =IF($P39="","",IF(INDEX('AFA Rates'!$L$5:$L$1004,$P39)="","—",INDEX('AFA Rates'!$L$5:$L$1004,$P39))) | K39: =IF($P39="","",IF(INDEX('AFA Rates'!$C$5:$C$1004,$P39)="","—",TEXT(INDEX('AFA Rates'!$C$5:$C$1004,$P39),"mm/dd/yyyy"))) | L39: =IF($P39="","",IF(INDEX('AFA Rates'!$D$5:$D$1004,$P39)="","—",TEXT(INDEX('AFA Rates'!$D$5:$D$1004,$P39),"mm/dd/yyyy"))) | M39: =IF($P39="","",INDEX('AFA Rates'!$O$5:$O$1004,$P39)) | P39: =IFERROR(MATCH(12,'AFA Rates'!$Q$5:$Q$1004,0),"")
B40: =IF($O$7="","",IF(COUNTIF('AFA Rates'!$A$5:$A$1004,$C$7)=0,"No AFA on file for this firm — standard rates apply.",""))
B42: RATE HISTORY (prior agreed rates)
B43: Schedule | C43: Counsel | D43: Senior Partner | E43: Junior Partner | F43: Partner | G43: Senior Associate | H43: Junior Associate | I43: Associate | J43: Paralegal | K43: From | L43: To | M43: Reason
B44: =IF($P44="","",IF(INDEX('Rate History'!$B$5:$B$2004,$P44)="","Standard",INDEX('Rate History'!$B$5:$B$2004,$P44))) | C44: =IF($P44="","",IF(INDEX('Rate History'!$E$5:$E$2004,$P44)="","—",INDEX('Rate History'!$E$5:$E$2004,$P44))) | D44: =IF($P44="","",IF(INDEX('Rate History'!$F$5:$F$2004,$P44)="","—",INDEX('Rate History'!$F$5:$F$2004,$P44))) | E44: =IF($P44="","",IF(INDEX('Rate History'!$G$5:$G$2004,$P44)="","—",INDEX('Rate History'!$G$5:$G$2004,$P44))) | F44: =IF($P44="","",IF(INDEX('Rate History'!$H$5:$H$2004,$P44)="","—",INDEX('Rate History'!$H$5:$H$2004,$P44))) | G44: =IF($P44="","",IF(INDEX('Rate History'!$I$5:$I$2004,$P44)="","—",INDEX('Rate History'!$I$5:$I$2004,$P44))) | H44: =IF($P44="","",IF(INDEX('Rate History'!$J$5:$J$2004,$P44)="","—",INDEX('Rate History'!$J$5:$J$2004,$P44))) | I44: =IF($P44="","",IF(INDEX('Rate History'!$K$5:$K$2004,$P44)="","—",INDEX('Rate History'!$K$5:$K$2004,$P44))) | J44: =IF($P44="","",IF(INDEX('Rate History'!$L$5:$L$2004,$P44)="","—",INDEX('Rate History'!$L$5:$L$2004,$P44))) | K44: =IF($P44="","",IF(INDEX('Rate History'!$C$5:$C$2004,$P44)="","—",TEXT(INDEX('Rate History'!$C$5:$C$2004,$P44),"mm/dd/yyyy"))) | L44: =IF($P44="","",IF(INDEX('Rate History'!$D$5:$D$2004,$P44)="","—",TEXT(INDEX('Rate History'!$D$5:$D$2004,$P44),"mm/dd/yyyy"))) | M44: =IF($P44="","",INDEX('Rate History'!$M$5:$M$2004,$P44)&"") | P44: =IFERROR(MATCH(1,'Rate History'!$Q$5:$Q$2004,0),"")
B45: =IF($P45="","",IF(INDEX('Rate History'!$B$5:$B$2004,$P45)="","Standard",INDEX('Rate History'!$B$5:$B$2004,$P45))) | C45: =IF($P45="","",IF(INDEX('Rate History'!$E$5:$E$2004,$P45)="","—",INDEX('Rate History'!$E$5:$E$2004,$P45))) | D45: =IF($P45="","",IF(INDEX('Rate History'!$F$5:$F$2004,$P45)="","—",INDEX('Rate History'!$F$5:$F$2004,$P45))) | E45: =IF($P45="","",IF(INDEX('Rate History'!$G$5:$G$2004,$P45)="","—",INDEX('Rate History'!$G$5:$G$2004,$P45))) | F45: =IF($P45="","",IF(INDEX('Rate History'!$H$5:$H$2004,$P45)="","—",INDEX('Rate History'!$H$5:$H$2004,$P45))) | G45: =IF($P45="","",IF(INDEX('Rate History'!$I$5:$I$2004,$P45)="","—",INDEX('Rate History'!$I$5:$I$2004,$P45))) | H45: =IF($P45="","",IF(INDEX('Rate History'!$J$5:$J$2004,$P45)="","—",INDEX('Rate History'!$J$5:$J$2004,$P45))) | I45: =IF($P45="","",IF(INDEX('Rate History'!$K$5:$K$2004,$P45)="","—",INDEX('Rate History'!$K$5:$K$2004,$P45))) | J45: =IF($P45="","",IF(INDEX('Rate History'!$L$5:$L$2004,$P45)="","—",INDEX('Rate History'!$L$5:$L$2004,$P45))) | K45: =IF($P45="","",IF(INDEX('Rate History'!$C$5:$C$2004,$P45)="","—",TEXT(INDEX('Rate History'!$C$5:$C$2004,$P45),"mm/dd/yyyy"))) | L45: =IF($P45="","",IF(INDEX('Rate History'!$D$5:$D$2004,$P45)="","—",TEXT(INDEX('Rate History'!$D$5:$D$2004,$P45),"mm/dd/yyyy"))) | M45: =IF($P45="","",INDEX('Rate History'!$M$5:$M$2004,$P45)&"") | P45: =IFERROR(MATCH(2,'Rate History'!$Q$5:$Q$2004,0),"")
B46: =IF($P46="","",IF(INDEX('Rate History'!$B$5:$B$2004,$P46)="","Standard",INDEX('Rate History'!$B$5:$B$2004,$P46))) | C46: =IF($P46="","",IF(INDEX('Rate History'!$E$5:$E$2004,$P46)="","—",INDEX('Rate History'!$E$5:$E$2004,$P46))) | D46: =IF($P46="","",IF(INDEX('Rate History'!$F$5:$F$2004,$P46)="","—",INDEX('Rate History'!$F$5:$F$2004,$P46))) | E46: =IF($P46="","",IF(INDEX('Rate History'!$G$5:$G$2004,$P46)="","—",INDEX('Rate History'!$G$5:$G$2004,$P46))) | F46: =IF($P46="","",IF(INDEX('Rate History'!$H$5:$H$2004,$P46)="","—",INDEX('Rate History'!$H$5:$H$2004,$P46))) | G46: =IF($P46="","",IF(INDEX('Rate History'!$I$5:$I$2004,$P46)="","—",INDEX('Rate History'!$I$5:$I$2004,$P46))) | H46: =IF($P46="","",IF(INDEX('Rate History'!$J$5:$J$2004,$P46)="","—",INDEX('Rate History'!$J$5:$J$2004,$P46))) | I46: =IF($P46="","",IF(INDEX('Rate History'!$K$5:$K$2004,$P46)="","—",INDEX('Rate History'!$K$5:$K$2004,$P46))) | J46: =IF($P46="","",IF(INDEX('Rate History'!$L$5:$L$2004,$P46)="","—",INDEX('Rate History'!$L$5:$L$2004,$P46))) | K46: =IF($P46="","",IF(INDEX('Rate History'!$C$5:$C$2004,$P46)="","—",TEXT(INDEX('Rate History'!$C$5:$C$2004,$P46),"mm/dd/yyyy"))) | L46: =IF($P46="","",IF(INDEX('Rate History'!$D$5:$D$2004,$P46)="","—",TEXT(INDEX('Rate History'!$D$5:$D$2004,$P46),"mm/dd/yyyy"))) | M46: =IF($P46="","",INDEX('Rate History'!$M$5:$M$2004,$P46)&"") | P46: =IFERROR(MATCH(3,'Rate History'!$Q$5:$Q$2004,0),"")
B47: =IF($P47="","",IF(INDEX('Rate History'!$B$5:$B$2004,$P47)="","Standard",INDEX('Rate History'!$B$5:$B$2004,$P47))) | C47: =IF($P47="","",IF(INDEX('Rate History'!$E$5:$E$2004,$P47)="","—",INDEX('Rate History'!$E$5:$E$2004,$P47))) | D47: =IF($P47="","",IF(INDEX('Rate History'!$F$5:$F$2004,$P47)="","—",INDEX('Rate History'!$F$5:$F$2004,$P47))) | E47: =IF($P47="","",IF(INDEX('Rate History'!$G$5:$G$2004,$P47)="","—",INDEX('Rate History'!$G$5:$G$2004,$P47))) | F47: =IF($P47="","",IF(INDEX('Rate History'!$H$5:$H$2004,$P47)="","—",INDEX('Rate History'!$H$5:$H$2004,$P47))) | G47: =IF($P47="","",IF(INDEX('Rate History'!$I$5:$I$2004,$P47)="","—",INDEX('Rate History'!$I$5:$I$2004,$P47))) | H47: =IF($P47="","",IF(INDEX('Rate History'!$J$5:$J$2004,$P47)="","—",INDEX('Rate History'!$J$5:$J$2004,$P47))) | I47: =IF($P47="","",IF(INDEX('Rate History'!$K$5:$K$2004,$P47)="","—",INDEX('Rate History'!$K$5:$K$2004,$P47))) | J47: =IF($P47="","",IF(INDEX('Rate History'!$L$5:$L$2004,$P47)="","—",INDEX('Rate History'!$L$5:$L$2004,$P47))) | K47: =IF($P47="","",IF(INDEX('Rate History'!$C$5:$C$2004,$P47)="","—",TEXT(INDEX('Rate History'!$C$5:$C$2004,$P47),"mm/dd/yyyy"))) | L47: =IF($P47="","",IF(INDEX('Rate History'!$D$5:$D$2004,$P47)="","—",TEXT(INDEX('Rate History'!$D$5:$D$2004,$P47),"mm/dd/yyyy"))) | M47: =IF($P47="","",INDEX('Rate History'!$M$5:$M$2004,$P47)&"") | P47: =IFERROR(MATCH(4,'Rate History'!$Q$5:$Q$2004,0),"")
B48: =IF($P48="","",IF(INDEX('Rate History'!$B$5:$B$2004,$P48)="","Standard",INDEX('Rate History'!$B$5:$B$2004,$P48))) | C48: =IF($P48="","",IF(INDEX('Rate History'!$E$5:$E$2004,$P48)="","—",INDEX('Rate History'!$E$5:$E$2004,$P48))) | D48: =IF($P48="","",IF(INDEX('Rate History'!$F$5:$F$2004,$P48)="","—",INDEX('Rate History'!$F$5:$F$2004,$P48))) | E48: =IF($P48="","",IF(INDEX('Rate History'!$G$5:$G$2004,$P48)="","—",INDEX('Rate History'!$G$5:$G$2004,$P48))) | F48: =IF($P48="","",IF(INDEX('Rate History'!$H$5:$H$2004,$P48)="","—",INDEX('Rate History'!$H$5:$H$2004,$P48))) | G48: =IF($P48="","",IF(INDEX('Rate History'!$I$5:$I$2004,$P48)="","—",INDEX('Rate History'!$I$5:$I$2004,$P48))) | H48: =IF($P48="","",IF(INDEX('Rate History'!$J$5:$J$2004,$P48)="","—",INDEX('Rate History'!$J$5:$J$2004,$P48))) | I48: =IF($P48="","",IF(INDEX('Rate History'!$K$5:$K$2004,$P48)="","—",INDEX('Rate History'!$K$5:$K$2004,$P48))) | J48: =IF($P48="","",IF(INDEX('Rate History'!$L$5:$L$2004,$P48)="","—",INDEX('Rate History'!$L$5:$L$2004,$P48))) | K48: =IF($P48="","",IF(INDEX('Rate History'!$C$5:$C$2004,$P48)="","—",TEXT(INDEX('Rate History'!$C$5:$C$2004,$P48),"mm/dd/yyyy"))) | L48: =IF($P48="","",IF(INDEX('Rate History'!$D$5:$D$2004,$P48)="","—",TEXT(INDEX('Rate History'!$D$5:$D$2004,$P48),"mm/dd/yyyy"))) | M48: =IF($P48="","",INDEX('Rate History'!$M$5:$M$2004,$P48)&"") | P48: =IFERROR(MATCH(5,'Rate History'!$Q$5:$Q$2004,0),"")
...

Sheet Rate Check
B2: ✅ Rate Check — Approve a Rate Submission
B3: Pick the firm, then enter one line per timekeeper. Blank Rate Schedule = Standard. Blank Date of Service = today. The agreed rate in effect on that date is pulled automatically (current rates or Rate History).
B5: Firm: | C5: Brookstone Legal | F5: ◄ type or pick ▼
B7: Showing results for: | C7: =IF($C$5="","",IFERROR(INDEX(Firms!$A$5:$A$1004,MATCH($C$5,Firms!$A$5:$A$1004,0)),IFERROR(INDEX(Firms_AZ,MATCH("*"&$C$5&"*",Firms_AZ,0)),"No matching firm found"))) | G7: =IF(OR($C$5="",ISNUMBER(MATCH($C$5,Firms!$A$5:$A$1004,0))),"",IF(COUNTIF(Firms!$A$5:$A$1004,"*"&$C$5&"*")>1,COUNTIF(Firms!$A$5:$A$1004,"*"&$C$5&"*")&" firms match — showing the first A–Z. Be more specific or use ▼.","")) | P7: =IFERROR(MATCH($C$7,Firms!$A$5:$A$1004,0),"")
B8: =IF($P$7="",IF($C$5="","Pick a firm above.","No firm matches — check spelling."),IF(INDEX(Firms!$B$5:$B$1004,$P$7)="Paused","⛔ FIRM IS PAUSED (Do Not Use) — confirm before approving"&IF(INDEX(Firms!$S$5:$S$1004,$P$7)<>"",": "&INDEX(Firms!$S$5:$S$1004,$P$7),""),"✓ ACTIVE firm"))
B10: Timekeeper (optional) | C10: Rate Schedule (blank = Standard) | D10: Role | E10: Date of Service (blank = today) | F10: Submitted Rate | G10: Agreed Rate (auto) | H10: Difference (auto) | I10: Result (auto) | J10: Source / Reason (auto)
B11: J. Rivera | D11: Partner | F11: 495 | G11: =IF(OR(D11="",$P$7=""),"",IF(ISNUMBER($T11),$T11,IF(N($V11)>0,$V11,""))) | H11: =IF(OR(G11="",F11=""),"",F11-G11) | I11: =IF(D11="",IF(F11="","","Pick a role"),IF($P$7="","Pick a firm above",IF(G11="","⚠ No agreed rate",IF(F11="","Enter submitted rate",IF(F11<=G11,"✓ Approve","✗ Exceeds by "&TEXT(F11-G11,"$#,##0")))))) | J11: =IF(OR(D11="",$P$7=""),"",IF(ISNUMBER($T11),IF($P11="Standard","Current standard rates","Current AFA — "&$P11)&" (eff. "&IF(IF($P11="Standard",INDEX(Firms!$E$5:$E$1004,$P$7),INDEX('AFA Rates'!$C$5:$C$1004,$S11))="","no date",TEXT(IF($P11="Standard",INDEX(Firms!$E$5:$E$1004,$P$7),INDEX('AFA Rates'!$C$5:$C$1004,$S11)),"mm/dd/yyyy"))&")",IF(N($V11)>0,"Rate History — "&$P11&" rates in effect on "&TEXT($Q11,"mm/dd/yyyy"),IF(N($U11)>1,"Overlapping Rate History rows — fix on Rate History tab",IF($T11="noafa","No "&$P11&" AFA on file for this firm",IF($T11="expired","AFA ended "&TEXT(INDEX('AFA Rates'!$D$5:$D$1004,$S11),"mm/dd/yyyy")&"; no Rate History row covers "&TEXT($Q11,"mm/dd/yyyy"),IF($T11="before","Date is before current rates; no Rate History row covers "&TEXT($Q11,"mm/dd/yyyy"),"No "&D11&" rate entered for "&$P11))))))) | P11: =IF(D11="","",IF(C11="","Standard",C11)) | Q11: =IF(D11="","",IF(E11="",TODAY(),E11)) | R11: =IFERROR(MATCH(D11,Role_List,0),"") | S11: =IF(OR($P11="",$P11="Standard",$P$7=""),"",IFERROR(MATCH($C$7&"|"&$P11,'AFA Rates'!$P$5:$P$1004,0),"")) | T11: =IF(OR($R11="",$P$7=""),"",IF($P11="Standard",IF(OR(INDEX(Firms!$E$5:$E$1004,$P$7)="",$Q11>=INDEX(Firms!$E$5:$E$1004,$P$7)),IF(INDEX(Firms!$F$5:$M$1004,$P$7,$R11)="","norate",INDEX(Firms!$F$5:$M$1004,$P$7,$R11)),"before"),IF($S11="","noafa",IF(AND(INDEX('AFA Rates'!$C$5:$C$1004,$S11)<>"",$Q11<INDEX('AFA Rates'!$C$5:$C$1004,$S11)),"before",IF(AND(INDEX('AFA Rates'!$D$5:$D$1004,$S11)<>"",$Q11>INDEX('AFA Rates'!$D$5:$D$1004,$S11)),"expired",IF(INDEX('AFA Rates'!$E$5:$L$1004,$S11,$R11)="","norate",INDEX('AFA Rates'!$E$5:$L$1004,$S11,$R11))))))) | U11: =IF(OR($R11="",$P$7=""),"",COUNTIFS('Rate History'!$P$5:$P$2004,$C$7&"|"&$P11,'Rate History'!$C$5:$C$2004,"<="&$Q11,'Rate History'!$D$5:$D$2004,">="&$Q11)) | V11: =IF(N($U11)<>1,"",SUMIFS(INDEX('Rate History'!$E$5:$L$2004,0,$R11),'Rate History'!$P$5:$P$2004,$C$7&"|"&$P11,'Rate History'!$C$5:$C$2004,"<="&$Q11,'Rate History'!$D$5:$D$2004,">="&$Q11))
B12: M. Chen | D12: Senior Partner | F12: 600 | G12: =IF(OR(D12="",$P$7=""),"",IF(ISNUMBER($T12),$T12,IF(N($V12)>0,$V12,""))) | H12: =IF(OR(G12="",F12=""),"",F12-G12) | I12: =IF(D12="",IF(F12="","","Pick a role"),IF($P$7="","Pick a firm above",IF(G12="","⚠ No agreed rate",IF(F12="","Enter submitted rate",IF(F12<=G12,"✓ Approve","✗ Exceeds by "&TEXT(F12-G12,"$#,##0")))))) | J12: =IF(OR(D12="",$P$7=""),"",IF(ISNUMBER($T12),IF($P12="Standard","Current standard rates","Current AFA — "&$P12)&" (eff. "&IF(IF($P12="Standard",INDEX(Firms!$E$5:$E$1004,$P$7),INDEX('AFA Rates'!$C$5:$C$1004,$S12))="","no date",TEXT(IF($P12="Standard",INDEX(Firms!$E$5:$E$1004,$P$7),INDEX('AFA Rates'!$C$5:$C$1004,$S12)),"mm/dd/yyyy"))&")",IF(N($V12)>0,"Rate History — "&$P12&" rates in effect on "&TEXT($Q12,"mm/dd/yyyy"),IF(N($U12)>1,"Overlapping Rate History rows — fix on Rate History tab",IF($T12="noafa","No "&$P12&" AFA on file for this firm",IF($T12="expired","AFA ended "&TEXT(INDEX('AFA Rates'!$D$5:$D$1004,$S12),"mm/dd/yyyy")&"; no Rate History row covers "&TEXT($Q12,"mm/dd/yyyy"),IF($T12="before","Date is before current rates; no Rate History row covers "&TEXT($Q12,"mm/dd/yyyy"),"No "&D12&" rate entered for "&$P12))))))) | P12: =IF(D12="","",IF(C12="","Standard",C12)) | Q12: =IF(D12="","",IF(E12="",TODAY(),E12)) | R12: =IFERROR(MATCH(D12,Role_List,0),"") | S12: =IF(OR($P12="",$P12="Standard",$P$7=""),"",IFERROR(MATCH($C$7&"|"&$P12,'AFA Rates'!$P$5:$P$1004,0),"")) | T12: =IF(OR($R12="",$P$7=""),"",IF($P12="Standard",IF(OR(INDEX(Firms!$E$5:$E$1004,$P$7)="",$Q12>=INDEX(Firms!$E$5:$E$1004,$P$7)),IF(INDEX(Firms!$F$5:$M$1004,$P$7,$R12)="","norate",INDEX(Firms!$F$5:$M$1004,$P$7,$R12)),"before"),IF($S12="","noafa",IF(AND(INDEX('AFA Rates'!$C$5:$C$1004,$S12)<>"",$Q12<INDEX('AFA Rates'!$C$5:$C$1004,$S12)),"before",IF(AND(INDEX('AFA Rates'!$D$5:$D$1004,$S12)<>"",$Q12>INDEX('AFA Rates'!$D$5:$D$1004,$S12)),"expired",IF(INDEX('AFA Rates'!$E$5:$L$1004,$S12,$R12)="","norate",INDEX('AFA Rates'!$E$5:$L$1004,$S12,$R12))))))) | U12: =IF(OR($R12="",$P$7=""),"",COUNTIFS('Rate History'!$P$5:$P$2004,$C$7&"|"&$P12,'Rate History'!$C$5:$C$2004,"<="&$Q12,'Rate History'!$D$5:$D$2004,">="&$Q12)) | V12: =IF(N($U12)<>1,"",SUMIFS(INDEX('Rate History'!$E$5:$L$2004,0,$R12),'Rate History'!$P$5:$P$2004,$C$7&"|"&$P12,'Rate History'!$C$5:$C$2004,"<="&$Q12,'Rate History'!$D$5:$D$2004,">="&$Q12))
B13: A. Patel | C13: Commercial Trucking | D13: Paralegal | F13: 135 | G13: =IF(OR(D13="",$P$7=""),"",IF(ISNUMBER($T13),$T13,IF(N($V13)>0,$V13,""))) | H13: =IF(OR(G13="",F13=""),"",F13-G13) | I13: =IF(D13="",IF(F13="","","Pick a role"),IF($P$7="","Pick a firm above",IF(G13="","⚠ No agreed rate",IF(F13="","Enter submitted rate",IF(F13<=G13,"✓ Approve","✗ Exceeds by "&TEXT(F13-G13,"$#,##0")))))) | J13: =IF(OR(D13="",$P$7=""),"",IF(ISNUMBER($T13),IF($P13="Standard","Current standard rates","Current AFA — "&$P13)&" (eff. "&IF(IF($P13="Standard",INDEX(Firms!$E$5:$E$1004,$P$7),INDEX('AFA Rates'!$C$5:$C$1004,$S13))="","no date",TEXT(IF($P13="Standard",INDEX(Firms!$E$5:$E$1004,$P$7),INDEX('AFA Rates'!$C$5:$C$1004,$S13)),"mm/dd/yyyy"))&")",IF(N($V13)>0,"Rate History — "&$P13&" rates in effect on "&TEXT($Q13,"mm/dd/yyyy"),IF(N($U13)>1,"Overlapping Rate History rows — fix on Rate History tab",IF($T13="noafa","No "&$P13&" AFA on file for this firm",IF($T13="expired","AFA ended "&TEXT(INDEX('AFA Rates'!$D$5:$D$1004,$S13),"mm/dd/yyyy")&"; no Rate History row covers "&TEXT($Q13,"mm/dd/yyyy"),IF($T13="before","Date is before current rates; no Rate History row covers "&TEXT($Q13,"mm/dd/yyyy"),"No "&D13&" rate entered for "&$P13))))))) | P13: =IF(D13="","",IF(C13="","Standard",C13)) | Q13: =IF(D13="","",IF(E13="",TODAY(),E13)) | R13: =IFERROR(MATCH(D13,Role_List,0),"") | S13: =IF(OR($P13="",$P13="Standard",$P$7=""),"",IFERROR(MATCH($C$7&"|"&$P13,'AFA Rates'!$P$5:$P$1004,0),"")) | T13: =IF(OR($R13="",$P$7=""),"",IF($P13="Standard",IF(OR(INDEX(Firms!$E$5:$E$1004,$P$7)="",$Q13>=INDEX(Firms!$E$5:$E$1004,$P$7)),IF(INDEX(Firms!$F$5:$M$1004,$P$7,$R13)="","norate",INDEX(Firms!$F$5:$M$1004,$P$7,$R13)),"before"),IF($S13="","noafa",IF(AND(INDEX('AFA Rates'!$C$5:$C$1004,$S13)<>"",$Q13<INDEX('AFA Rates'!$C$5:$C$1004,$S13)),"before",IF(AND(INDEX('AFA Rates'!$D$5:$D$1004,$S13)<>"",$Q13>INDEX('AFA Rates'!$D$5:$D$1004,$S13)),"expired",IF(INDEX('AFA Rates'!$E$5:$L$1004,$S13,$R13)="","norate",INDEX('AFA Rates'!$E$5:$L$1004,$S13,$R13))))))) | U13: =IF(OR($R13="",$P$7=""),"",COUNTIFS('Rate History'!$P$5:$P$2004,$C$7&"|"&$P13,'Rate History'!$C$5:$C$2004,"<="&$Q13,'Rate History'!$D$5:$D$2004,">="&$Q13)) | V13: =IF(N($U13)<>1,"",SUMIFS(INDEX('Rate History'!$E$5:$L$2004,0,$R13),'Rate History'!$P$5:$P$2004,$C$7&"|"&$P13,'Rate History'!$C$5:$C$2004,"<="&$Q13,'Rate History'!$D$5:$D$2004,">="&$Q13))
B14: J. Rivera | D14: Partner | E14: 45823 | F14: 495 | G14: =IF(OR(D14="",$P$7=""),"",IF(ISNUMBER($T14),$T14,IF(N($V14)>0,$V14,""))) | H14: =IF(OR(G14="",F14=""),"",F14-G14) | I14: =IF(D14="",IF(F14="","","Pick a role"),IF($P$7="","Pick a firm above",IF(G14="","⚠ No agreed rate",IF(F14="","Enter submitted rate",IF(F14<=G14,"✓ Approve","✗ Exceeds by "&TEXT(F14-G14,"$#,##0")))))) | J14: =IF(OR(D14="",$P$7=""),"",IF(ISNUMBER($T14),IF($P14="Standard","Current standard rates","Current AFA — "&$P14)&" (eff. "&IF(IF($P14="Standard",INDEX(Firms!$E$5:$E$1004,$P$7),INDEX('AFA Rates'!$C$5:$C$1004,$S14))="","no date",TEXT(IF($P14="Standard",INDEX(Firms!$E$5:$E$1004,$P$7),INDEX('AFA Rates'!$C$5:$C$1004,$S14)),"mm/dd/yyyy"))&")",IF(N($V14)>0,"Rate History — "&$P14&" rates in effect on "&TEXT($Q14,"mm/dd/yyyy"),IF(N($U14)>1,"Overlapping Rate History rows — fix on Rate History tab",IF($T14="noafa","No "&$P14&" AFA on file for this firm",IF($T14="expired","AFA ended "&TEXT(INDEX('AFA Rates'!$D$5:$D$1004,$S14),"mm/dd/yyyy")&"; no Rate History row covers "&TEXT($Q14,"mm/dd/yyyy"),IF($T14="before","Date is before current rates; no Rate History row covers "&TEXT($Q14,"mm/dd/yyyy"),"No "&D14&" rate entered for "&$P14))))))) | P14: =IF(D14="","",IF(C14="","Standard",C14)) | Q14: =IF(D14="","",IF(E14="",TODAY(),E14)) | R14: =IFERROR(MATCH(D14,Role_List,0),"") | S14: =IF(OR($P14="",$P14="Standard",$P$7=""),"",IFERROR(MATCH($C$7&"|"&$P14,'AFA Rates'!$P$5:$P$1004,0),"")) | T14: =IF(OR($R14="",$P$7=""),"",IF($P14="Standard",IF(OR(INDEX(Firms!$E$5:$E$1004,$P$7)="",$Q14>=INDEX(Firms!$E$5:$E$1004,$P$7)),IF(INDEX(Firms!$F$5:$M$1004,$P$7,$R14)="","norate",INDEX(Firms!$F$5:$M$1004,$P$7,$R14)),"before"),IF($S14="","noafa",IF(AND(INDEX('AFA Rates'!$C$5:$C$1004,$S14)<>"",$Q14<INDEX('AFA Rates'!$C$5:$C$1004,$S14)),"before",IF(AND(INDEX('AFA Rates'!$D$5:$D$1004,$S14)<>"",$Q14>INDEX('AFA Rates'!$D$5:$D$1004,$S14)),"expired",IF(INDEX('AFA Rates'!$E$5:$L$1004,$S14,$R14)="","norate",INDEX('AFA Rates'!$E$5:$L$1004,$S14,$R14))))))) | U14: =IF(OR($R14="",$P$7=""),"",COUNTIFS('Rate History'!$P$5:$P$2004,$C$7&"|"&$P14,'Rate History'!$C$5:$C$2004,"<="&$Q14,'Rate History'!$D$5:$D$2004,">="&$Q14)) | V14: =IF(N($U14)<>1,"",SUMIFS(INDEX('Rate History'!$E$5:$L$2004,0,$R14),'Rate History'!$P$5:$P$2004,$C$7&"|"&$P14,'Rate History'!$C$5:$C$2004,"<="&$Q14,'Rate History'!$D$5:$D$2004,">="&$Q14))
B15: K. Osei | C15: Appellate | D15: Associate | F15: 300 | G15: =IF(OR(D15="",$P$7=""),"",IF(ISNUMBER($T15),$T15,IF(N($V15)>0,$V15,""))) | H15: =IF(OR(G15="",F15=""),"",F15-G15) | I15: =IF(D15="",IF(F15="","","Pick a role"),IF($P$7="","Pick a firm above",IF(G15="","⚠ No agreed rate",IF(F15="","Enter submitted rate",IF(F15<=G15,"✓ Approve","✗ Exceeds by "&TEXT(F15-G15,"$#,##0")))))) | J15: =IF(OR(D15="",$P$7=""),"",IF(ISNUMBER($T15),IF($P15="Standard","Current standard rates","Current AFA — "&$P15)&" (eff. "&IF(IF($P15="Standard",INDEX(Firms!$E$5:$E$1004,$P$7),INDEX('AFA Rates'!$C$5:$C$1004,$S15))="","no date",TEXT(IF($P15="Standard",INDEX(Firms!$E$5:$E$1004,$P$7),INDEX('AFA Rates'!$C$5:$C$1004,$S15)),"mm/dd/yyyy"))&")",IF(N($V15)>0,"Rate History — "&$P15&" rates in effect on "&TEXT($Q15,"mm/dd/yyyy"),IF(N($U15)>1,"Overlapping Rate History rows — fix on Rate History tab",IF($T15="noafa","No "&$P15&" AFA on file for this firm",IF($T15="expired","AFA ended "&TEXT(INDEX('AFA Rates'!$D$5:$D$1004,$S15),"mm/dd/yyyy")&"; no Rate History row covers "&TEXT($Q15,"mm/dd/yyyy"),IF($T15="before","Date is before current rates; no Rate History row covers "&TEXT($Q15,"mm/dd/yyyy"),"No "&D15&" rate entered for "&$P15))))))) | P15: =IF(D15="","",IF(C15="","Standard",C15)) | Q15: =IF(D15="","",IF(E15="",TODAY(),E15)) | R15: =IFERROR(MATCH(D15,Role_List,0),"") | S15: =IF(OR($P15="",$P15="Standard",$P$7=""),"",IFERROR(MATCH($C$7&"|"&$P15,'AFA Rates'!$P$5:$P$1004,0),"")) | T15: =IF(OR($R15="",$P$7=""),"",IF($P15="Standard",IF(OR(INDEX(Firms!$E$5:$E$1004,$P$7)="",$Q15>=INDEX(Firms!$E$5:$E$1004,$P$7)),IF(INDEX(Firms!$F$5:$M$1004,$P$7,$R15)="","norate",INDEX(Firms!$F$5:$M$1004,$P$7,$R15)),"before"),IF($S15="","noafa",IF(AND(INDEX('AFA Rates'!$C$5:$C$1004,$S15)<>"",$Q15<INDEX('AFA Rates'!$C$5:$C$1004,$S15)),"before",IF(AND(INDEX('AFA Rates'!$D$5:$D$1004,$S15)<>"",$Q15>INDEX('AFA Rates'!$D$5:$D$1004,$S15)),"expired",IF(INDEX('AFA Rates'!$E$5:$L$1004,$S15,$R15)="","norate",INDEX('AFA Rates'!$E$5:$L$1004,$S15,$R15))))))) | U15: =IF(OR($R15="",$P$7=""),"",COUNTIFS('Rate History'!$P$5:$P$2004,$C$7&"|"&$P15,'Rate History'!$C$5:$C$2004,"<="&$Q15,'Rate History'!$D$5:$D$2004,">="&$Q15)) | V15: =IF(N($U15)<>1,"",SUMIFS(INDEX('Rate History'!$E$5:$L$2004,0,$R15),'Rate History'!$P$5:$P$2004,$C$7&"|"&$P15,'Rate History'!$C$5:$C$2004,"<="&$Q15,'Rate History'!$D$5:$D$2004,">="&$Q15))
G16: =IF(OR(D16="",$P$7=""),"",IF(ISNUMBER($T16),$T16,IF(N($V16)>0,$V16,""))) | H16: =IF(OR(G16="",F16=""),"",F16-G16) | I16: =IF(D16="",IF(F16="","","Pick a role"),IF($P$7="","Pick a firm above",IF(G16="","⚠ No agreed rate",IF(F16="","Enter submitted rate",IF(F16<=G16,"✓ Approve","✗ Exceeds by "&TEXT(F16-G16,"$#,##0")))))) | J16: =IF(OR(D16="",$P$7=""),"",IF(ISNUMBER($T16),IF($P16="Standard","Current standard rates","Current AFA — "&$P16)&" (eff. "&IF(IF($P16="Standard",INDEX(Firms!$E$5:$E$1004,$P$7),INDEX('AFA Rates'!$C$5:$C$1004,$S16))="","no date",TEXT(IF($P16="Standard",INDEX(Firms!$E$5:$E$1004,$P$7),INDEX('AFA Rates'!$C$5:$C$1004,$S16)),"mm/dd/yyyy"))&")",IF(N($V16)>0,"Rate History — "&$P16&" rates in effect on "&TEXT($Q16,"mm/dd/yyyy"),IF(N($U16)>1,"Overlapping Rate History rows — fix on Rate History tab",IF($T16="noafa","No "&$P16&" AFA on file for this firm",IF($T16="expired","AFA ended "&TEXT(INDEX('AFA Rates'!$D$5:$D$1004,$S16),"mm/dd/yyyy")&"; no Rate History row covers "&TEXT($Q16,"mm/dd/yyyy"),IF($T16="before","Date is before current rates; no Rate History row covers "&TEXT($Q16,"mm/dd/yyyy"),"No "&D16&" rate entered for "&$P16))))))) | P16: =IF(D16="","",IF(C16="","Standard",C16)) | Q16: =IF(D16="","",IF(E16="",TODAY(),E16)) | R16: =IFERROR(MATCH(D16,Role_List,0),"") | S16: =IF(OR($P16="",$P16="Standard",$P$7=""),"",IFERROR(MATCH($C$7&"|"&$P16,'AFA Rates'!$P$5:$P$1004,0),"")) | T16: =IF(OR($R16="",$P$7=""),"",IF($P16="Standard",IF(OR(INDEX(Firms!$E$5:$E$1004,$P$7)="",$Q16>=INDEX(Firms!$E$5:$E$1004,$P$7)),IF(INDEX(Firms!$F$5:$M$1004,$P$7,$R16)="","norate",INDEX(Firms!$F$5:$M$1004,$P$7,$R16)),"before"),IF($S16="","noafa",IF(AND(INDEX('AFA Rates'!$C$5:$C$1004,$S16)<>"",$Q16<INDEX('AFA Rates'!$C$5:$C$1004,$S16)),"before",IF(AND(INDEX('AFA Rates'!$D$5:$D$1004,$S16)<>"",$Q16>INDEX('AFA Rates'!$D$5:$D$1004,$S16)),"expired",IF(INDEX('AFA Rates'!$E$5:$L$1004,$S16,$R16)="","norate",INDEX('AFA Rates'!$E$5:$L$1004,$S16,$R16))))))) | U16: =IF(OR($R16="",$P$7=""),"",COUNTIFS('Rate History'!$P$5:$P$2004,$C$7&"|"&$P16,'Rate History'!$C$5:$C$2004,"<="&$Q16,'Rate History'!$D$5:$D$2004,">="&$Q16)) | V16: =IF(N($U16)<>1,"",SUMIFS(INDEX('Rate History'!$E$5:$L$2004,0,$R16),'Rate History'!$P$5:$P$2004,$C$7&"|"&$P16,'Rate History'!$C$5:$C$2004,"<="&$Q16,'Rate History'!$D$5:$D$2004,">="&$Q16))
G17: =IF(OR(D17="",$P$7=""),"",IF(ISNUMBER($T17),$T17,IF(N($V17)>0,$V17,""))) | H17: =IF(OR(G17="",F17=""),"",F17-G17) | I17: =IF(D17="",IF(F17="","","Pick a role"),IF($P$7="","Pick a firm above",IF(G17="","⚠ No agreed rate",IF(F17="","Enter submitted rate",IF(F17<=G17,"✓ Approve","✗ Exceeds by "&TEXT(F17-G17,"$#,##0")))))) | J17: =IF(OR(D17="",$P$7=""),"",IF(ISNUMBER($T17),IF($P17="Standard","Current standard rates","Current AFA — "&$P17)&" (eff. "&IF(IF($P17="Standard",INDEX(Firms!$E$5:$E$1004,$P$7),INDEX('AFA Rates'!$C$5:$C$1004,$S17))="","no date",TEXT(IF($P17="Standard",INDEX(Firms!$E$5:$E$1004,$P$7),INDEX('AFA Rates'!$C$5:$C$1004,$S17)),"mm/dd/yyyy"))&")",IF(N($V17)>0,"Rate History — "&$P17&" rates in effect on "&TEXT($Q17,"mm/dd/yyyy"),IF(N($U17)>1,"Overlapping Rate History rows — fix on Rate History tab",IF($T17="noafa","No "&$P17&" AFA on file for this firm",IF($T17="expired","AFA ended "&TEXT(INDEX('AFA Rates'!$D$5:$D$1004,$S17),"mm/dd/yyyy")&"; no Rate History row covers "&TEXT($Q17,"mm/dd/yyyy"),IF($T17="before","Date is before current rates; no Rate History row covers "&TEXT($Q17,"mm/dd/yyyy"),"No "&D17&" rate entered for "&$P17))))))) | P17: =IF(D17="","",IF(C17="","Standard",C17)) | Q17: =IF(D17="","",IF(E17="",TODAY(),E17)) | R17: =IFERROR(MATCH(D17,Role_List,0),"") | S17: =IF(OR($P17="",$P17="Standard",$P$7=""),"",IFERROR(MATCH($C$7&"|"&$P17,'AFA Rates'!$P$5:$P$1004,0),"")) | T17: =IF(OR($R17="",$P$7=""),"",IF($P17="Standard",IF(OR(INDEX(Firms!$E$5:$E$1004,$P$7)="",$Q17>=INDEX(Firms!$E$5:$E$1004,$P$7)),IF(INDEX(Firms!$F$5:$M$1004,$P$7,$R17)="","norate",INDEX(Firms!$F$5:$M$1004,$P$7,$R17)),"before"),IF($S17="","noafa",IF(AND(INDEX('AFA Rates'!$C$5:$C$1004,$S17)<>"",$Q17<INDEX('AFA Rates'!$C$5:$C$1004,$S17)),"before",IF(AND(INDEX('AFA Rates'!$D$5:$D$1004,$S17)<>"",$Q17>INDEX('AFA Rates'!$D$5:$D$1004,$S17)),"expired",IF(INDEX('AFA Rates'!$E$5:$L$1004,$S17,$R17)="","norate",INDEX('AFA Rates'!$E$5:$L$1004,$S17,$R17))))))) | U17: =IF(OR($R17="",$P$7=""),"",COUNTIFS('Rate History'!$P$5:$P$2004,$C$7&"|"&$P17,'Rate History'!$C$5:$C$2004,"<="&$Q17,'Rate History'!$D$5:$D$2004,">="&$Q17)) | V17: =IF(N($U17)<>1,"",SUMIFS(INDEX('Rate History'!$E$5:$L$2004,0,$R17),'Rate History'!$P$5:$P$2004,$C$7&"|"&$P17,'Rate History'!$C$5:$C$2004,"<="&$Q17,'Rate History'!$D$5:$D$2004,">="&$Q17))
G18: =IF(OR(D18="",$P$7=""),"",IF(ISNUMBER($T18),$T18,IF(N($V18)>0,$V18,""))) | H18: =IF(OR(G18="",F18=""),"",F18-G18) | I18: =IF(D18="",IF(F18="","","Pick a role"),IF($P$7="","Pick a firm above",IF(G18="","⚠ No agreed rate",IF(F18="","Enter submitted rate",IF(F18<=G18,"✓ Approve","✗ Exceeds by "&TEXT(F18-G18,"$#,##0")))))) | J18: =IF(OR(D18="",$P$7=""),"",IF(ISNUMBER($T18),IF($P18="Standard","Current standard rates","Current AFA — "&$P18)&" (eff. "&IF(IF($P18="Standard",INDEX(Firms!$E$5:$E$1004,$P$7),INDEX('AFA Rates'!$C$5:$C$1004,$S18))="","no date",TEXT(IF($P18="Standard",INDEX(Firms!$E$5:$E$1004,$P$7),INDEX('AFA Rates'!$C$5:$C$1004,$S18)),"mm/dd/yyyy"))&")",IF(N($V18)>0,"Rate History — "&$P18&" rates in effect on "&TEXT($Q18,"mm/dd/yyyy"),IF(N($U18)>1,"Overlapping Rate History rows — fix on Rate History tab",IF($T18="noafa","No "&$P18&" AFA on file for this firm",IF($T18="expired","AFA ended "&TEXT(INDEX('AFA Rates'!$D$5:$D$1004,$S18),"mm/dd/yyyy")&"; no Rate History row covers "&TEXT($Q18,"mm/dd/yyyy"),IF($T18="before","Date is before current rates; no Rate History row covers "&TEXT($Q18,"mm/dd/yyyy"),"No "&D18&" rate entered for "&$P18))))))) | P18: =IF(D18="","",IF(C18="","Standard",C18)) | Q18: =IF(D18="","",IF(E18="",TODAY(),E18)) | R18: =IFERROR(MATCH(D18,Role_List,0),"") | S18: =IF(OR($P18="",$P18="Standard",$P$7=""),"",IFERROR(MATCH($C$7&"|"&$P18,'AFA Rates'!$P$5:$P$1004,0),"")) | T18: =IF(OR($R18="",$P$7=""),"",IF($P18="Standard",IF(OR(INDEX(Firms!$E$5:$E$1004,$P$7)="",$Q18>=INDEX(Firms!$E$5:$E$1004,$P$7)),IF(INDEX(Firms!$F$5:$M$1004,$P$7,$R18)="","norate",INDEX(Firms!$F$5:$M$1004,$P$7,$R18)),"before"),IF($S18="","noafa",IF(AND(INDEX('AFA Rates'!$C$5:$C$1004,$S18)<>"",$Q18<INDEX('AFA Rates'!$C$5:$C$1004,$S18)),"before",IF(AND(INDEX('AFA Rates'!$D$5:$D$1004,$S18)<>"",$Q18>INDEX('AFA Rates'!$D$5:$D$1004,$S18)),"expired",IF(INDEX('AFA Rates'!$E$5:$L$1004,$S18,$R18)="","norate",INDEX('AFA Rates'!$E$5:$L$1004,$S18,$R18))))))) | U18: =IF(OR($R18="",$P$7=""),"",COUNTIFS('Rate History'!$P$5:$P$2004,$C$7&"|"&$P18,'Rate History'!$C$5:$C$2004,"<="&$Q18,'Rate History'!$D$5:$D$2004,">="&$Q18)) | V18: =IF(N($U18)<>1,"",SUMIFS(INDEX('Rate History'!$E$5:$L$2004,0,$R18),'Rate History'!$P$5:$P$2004,$C$7&"|"&$P18,'Rate History'!$C$5:$C$2004,"<="&$Q18,'Rate History'!$D$5:$D$2004,">="&$Q18))
G19: =IF(OR(D19="",$P$7=""),"",IF(ISNUMBER($T19),$T19,IF(N($V19)>0,$V19,""))) | H19: =IF(OR(G19="",F19=""),"",F19-G19) | I19: =IF(D19="",IF(F19="","","Pick a role"),IF($P$7="","Pick a firm above",IF(G19="","⚠ No agreed rate",IF(F19="","Enter submitted rate",IF(F19<=G19,"✓ Approve","✗ Exceeds by "&TEXT(F19-G19,"$#,##0")))))) | J19: =IF(OR(D19="",$P$7=""),"",IF(ISNUMBER($T19),IF($P19="Standard","Current standard rates","Current AFA — "&$P19)&" (eff. "&IF(IF($P19="Standard",INDEX(Firms!$E$5:$E$1004,$P$7),INDEX('AFA Rates'!$C$5:$C$1004,$S19))="","no date",TEXT(IF($P19="Standard",INDEX(Firms!$E$5:$E$1004,$P$7),INDEX('AFA Rates'!$C$5:$C$1004,$S19)),"mm/dd/yyyy"))&")",IF(N($V19)>0,"Rate History — "&$P19&" rates in effect on "&TEXT($Q19,"mm/dd/yyyy"),IF(N($U19)>1,"Overlapping Rate History rows — fix on Rate History tab",IF($T19="noafa","No "&$P19&" AFA on file for this firm",IF($T19="expired","AFA ended "&TEXT(INDEX('AFA Rates'!$D$5:$D$1004,$S19),"mm/dd/yyyy")&"; no Rate History row covers "&TEXT($Q19,"mm/dd/yyyy"),IF($T19="before","Date is before current rates; no Rate History row covers "&TEXT($Q19,"mm/dd/yyyy"),"No "&D19&" rate entered for "&$P19))))))) | P19: =IF(D19="","",IF(C19="","Standard",C19)) | Q19: =IF(D19="","",IF(E19="",TODAY(),E19)) | R19: =IFERROR(MATCH(D19,Role_List,0),"") | S19: =IF(OR($P19="",$P19="Standard",$P$7=""),"",IFERROR(MATCH($C$7&"|"&$P19,'AFA Rates'!$P$5:$P$1004,0),"")) | T19: =IF(OR($R19="",$P$7=""),"",IF($P19="Standard",IF(OR(INDEX(Firms!$E$5:$E$1004,$P$7)="",$Q19>=INDEX(Firms!$E$5:$E$1004,$P$7)),IF(INDEX(Firms!$F$5:$M$1004,$P$7,$R19)="","norate",INDEX(Firms!$F$5:$M$1004,$P$7,$R19)),"before"),IF($S19="","noafa",IF(AND(INDEX('AFA Rates'!$C$5:$C$1004,$S19)<>"",$Q19<INDEX('AFA Rates'!$C$5:$C$1004,$S19)),"before",IF(AND(INDEX('AFA Rates'!$D$5:$D$1004,$S19)<>"",$Q19>INDEX('AFA Rates'!$D$5:$D$1004,$S19)),"expired",IF(INDEX('AFA Rates'!$E$5:$L$1004,$S19,$R19)="","norate",INDEX('AFA Rates'!$E$5:$L$1004,$S19,$R19))))))) | U19: =IF(OR($R19="",$P$7=""),"",COUNTIFS('Rate History'!$P$5:$P$2004,$C$7&"|"&$P19,'Rate History'!$C$5:$C$2004,"<="&$Q19,'Rate History'!$D$5:$D$2004,">="&$Q19)) | V19: =IF(N($U19)<>1,"",SUMIFS(INDEX('Rate History'!$E$5:$L$2004,0,$R19),'Rate History'!$P$5:$P$2004,$C$7&"|"&$P19,'Rate History'!$C$5:$C$2004,"<="&$Q19,'Rate History'!$D$5:$D$2004,">="&$Q19))
G20: =IF(OR(D20="",$P$7=""),"",IF(ISNUMBER($T20),$T20,IF(N($V20)>0,$V20,""))) | H20: =IF(OR(G20="",F20=""),"",F20-G20) | I20: =IF(D20="",IF(F20="","","Pick a role"),IF($P$7="","Pick a firm above",IF(G20="","⚠ No agreed rate",IF(F20="","Enter submitted rate",IF(F20<=G20,"✓ Approve","✗ Exceeds by "&TEXT(F20-G20,"$#,##0")))))) | J20: =IF(OR(D20="",$P$7=""),"",IF(ISNUMBER($T20),IF($P20="Standard","Current standard rates","Current AFA — "&$P20)&" (eff. "&IF(IF($P20="Standard",INDEX(Firms!$E$5:$E$1004,$P$7),INDEX('AFA Rates'!$C$5:$C$1004,$S20))="","no date",TEXT(IF($P20="Standard",INDEX(Firms!$E$5:$E$1004,$P$7),INDEX('AFA Rates'!$C$5:$C$1004,$S20)),"mm/dd/yyyy"))&")",IF(N($V20)>0,"Rate History — "&$P20&" rates in effect on "&TEXT($Q20,"mm/dd/yyyy"),IF(N($U20)>1,"Overlapping Rate History rows — fix on Rate History tab",IF($T20="noafa","No "&$P20&" AFA on file for this firm",IF($T20="expired","AFA ended "&TEXT(INDEX('AFA Rates'!$D$5:$D$1004,$S20),"mm/dd/yyyy")&"; no Rate History row covers "&TEXT($Q20,"mm/dd/yyyy"),IF($T20="before","Date is before current rates; no Rate History row covers "&TEXT($Q20,"mm/dd/yyyy"),"No "&D20&" rate entered for "&$P20))))))) | P20: =IF(D20="","",IF(C20="","Standard",C20)) | Q20: =IF(D20="","",IF(E20="",TODAY(),E20)) | R20: =IFERROR(MATCH(D20,Role_List,0),"") | S20: =IF(OR($P20="",$P20="Standard",$P$7=""),"",IFERROR(MATCH($C$7&"|"&$P20,'AFA Rates'!$P$5:$P$1004,0),"")) | T20: =IF(OR($R20="",$P$7=""),"",IF($P20="Standard",IF(OR(INDEX(Firms!$E$5:$E$1004,$P$7)="",$Q20>=INDEX(Firms!$E$5:$E$1004,$P$7)),IF(INDEX(Firms!$F$5:$M$1004,$P$7,$R20)="","norate",INDEX(Firms!$F$5:$M$1004,$P$7,$R20)),"before"),IF($S20="","noafa",IF(AND(INDEX('AFA Rates'!$C$5:$C$1004,$S20)<>"",$Q20<INDEX('AFA Rates'!$C$5:$C$1004,$S20)),"before",IF(AND(INDEX('AFA Rates'!$D$5:$D$1004,$S20)<>"",$Q20>INDEX('AFA Rates'!$D$5:$D$1004,$S20)),"expired",IF(INDEX('AFA Rates'!$E$5:$L$1004,$S20,$R20)="","norate",INDEX('AFA Rates'!$E$5:$L$1004,$S20,$R20))))))) | U20: =IF(OR($R20="",$P$7=""),"",COUNTIFS('Rate History'!$P$5:$P$2004,$C$7&"|"&$P20,'Rate History'!$C$5:$C$2004,"<="&$Q20,'Rate History'!$D$5:$D$2004,">="&$Q20)) | V20: =IF(N($U20)<>1,"",SUMIFS(INDEX('Rate History'!$E$5:$L$2004,0,$R20),'Rate History'!$P$5:$P$2004,$C$7&"|"&$P20,'Rate History'!$C$5:$C$2004,"<="&$Q20,'Rate History'!$D$5:$D$2004,">="&$Q20))
G21: =IF(OR(D21="",$P$7=""),"",IF(ISNUMBER($T21),$T21,IF(N($V21)>0,$V21,""))) | H21: =IF(OR(G21="",F21=""),"",F21-G21) | I21: =IF(D21="",IF(F21="","","Pick a role"),IF($P$7="","Pick a firm above",IF(G21="","⚠ No agreed rate",IF(F21="","Enter submitted rate",IF(F21<=G21,"✓ Approve","✗ Exceeds by "&TEXT(F21-G21,"$#,##0")))))) | J21: =IF(OR(D21="",$P$7=""),"",IF(ISNUMBER($T21),IF($P21="Standard","Current standard rates","Current AFA — "&$P21)&" (eff. "&IF(IF($P21="Standard",INDEX(Firms!$E$5:$E$1004,$P$7),INDEX('AFA Rates'!$C$5:$C$1004,$S21))="","no date",TEXT(IF($P21="Standard",INDEX(Firms!$E$5:$E$1004,$P$7),INDEX('AFA Rates'!$C$5:$C$1004,$S21)),"mm/dd/yyyy"))&")",IF(N($V21)>0,"Rate History — "&$P21&" rates in effect on "&TEXT($Q21,"mm/dd/yyyy"),IF(N($U21)>1,"Overlapping Rate History rows — fix on Rate History tab",IF($T21="noafa","No "&$P21&" AFA on file for this firm",IF($T21="expired","AFA ended "&TEXT(INDEX('AFA Rates'!$D$5:$D$1004,$S21),"mm/dd/yyyy")&"; no Rate History row covers "&TEXT($Q21,"mm/dd/yyyy"),IF($T21="before","Date is before current rates; no Rate History row covers "&TEXT($Q21,"mm/dd/yyyy"),"No "&D21&" rate entered for "&$P21))))))) | P21: =IF(D21="","",IF(C21="","Standard",C21)) | Q21: =IF(D21="","",IF(E21="",TODAY(),E21)) | R21: =IFERROR(MATCH(D21,Role_List,0),"") | S21: =IF(OR($P21="",$P21="Standard",$P$7=""),"",IFERROR(MATCH($C$7&"|"&$P21,'AFA Rates'!$P$5:$P$1004,0),"")) | T21: =IF(OR($R21="",$P$7=""),"",IF($P21="Standard",IF(OR(INDEX(Firms!$E$5:$E$1004,$P$7)="",$Q21>=INDEX(Firms!$E$5:$E$1004,$P$7)),IF(INDEX(Firms!$F$5:$M$1004,$P$7,$R21)="","norate",INDEX(Firms!$F$5:$M$1004,$P$7,$R21)),"before"),IF($S21="","noafa",IF(AND(INDEX('AFA Rates'!$C$5:$C$1004,$S21)<>"",$Q21<INDEX('AFA Rates'!$C$5:$C$1004,$S21)),"before",IF(AND(INDEX('AFA Rates'!$D$5:$D$1004,$S21)<>"",$Q21>INDEX('AFA Rates'!$D$5:$D$1004,$S21)),"expired",IF(INDEX('AFA Rates'!$E$5:$L$1004,$S21,$R21)="","norate",INDEX('AFA Rates'!$E$5:$L$1004,$S21,$R21))))))) | U21: =IF(OR($R21="",$P$7=""),"",COUNTIFS('Rate History'!$P$5:$P$2004,$C$7&"|"&$P21,'Rate History'!$C$5:$C$2004,"<="&$Q21,'Rate History'!$D$5:$D$2004,">="&$Q21)) | V21: =IF(N($U21)<>1,"",SUMIFS(INDEX('Rate History'!$E$5:$L$2004,0,$R21),'Rate History'!$P$5:$P$2004,$C$7&"|"&$P21,'Rate History'!$C$5:$C$2004,"<="&$Q21,'Rate History'!$D$5:$D$2004,">="&$Q21))
